<?xml version="1.0" encoding="utf-8"?>
<!-- This URDF was automatically created by SolidWorks to URDF Exporter! Originally created by Stephen Brawner (brawner@gmail.com) 
     Commit Version: 1.6.0-4-g7f85cfe  Build Version: 1.6.7995.38578
     For more information, please see http://wiki.ros.org/sw_urdf_exporter -->
<robot
  name="ramiel2">
  <link
    name="base_link">
    <inertial>
      <origin
        xyz="-0.0163 0.0056 -0.00642"
        rpy="0 0 0" />
      <mass
        value="13.959" />
      <inertia
        ixx="0.58153312113"
        ixy="0.00047377296"
        ixz="0.01002995747"
        iyy="0.62883843864"
        iyz="-0.00135094509"
        izz="1.10481157886" />
    </inertial>
    <visual>
      <origin
        xyz="0 0 0"
        rpy="0 0 0" />
      <geometry>
        <mesh
          filename="../meshes/base_link.STL" />
      </geometry>
      <material
        name="">
        <color
          rgba="0.792156862745098 0.819607843137255 0.933333333333333 1" />
      </material>
    </visual>
    <collision>
      <origin
        xyz="0 0 0"
        rpy="0 0 0" />
      <geometry>
        <box size="0.5 0.5 0.2"/>
      </geometry>
    </collision>
  </link>
  <link
    name="roll_pitch_link">
    <inertial>
      <origin
        xyz="-0.00089 0.0 0.00520"
        rpy="0 0 0" />
      <mass
        value="0.41229" />
      <inertia
        ixx="0.00063411708"
        ixy="1.4203e-7"
        ixz="0.00000170051"
        iyy="0.00193834263"
        iyz="3.96e-9"
        izz="0.00150421906" />
    </inertial>
    <visual>
      <origin
        xyz="0 0 0"
        rpy="0 0 0" />
      <geometry>
        <mesh
          filename="../meshes/roll_pitch_link.STL" />
      </geometry>
      <material
        name="">
        <color
          rgba="0.792156862745098 0.819607843137255 0.933333333333333 1" />
      </material>
    </visual>
  </link>
  <joint
    name="roll"
    type="revolute">
    <origin
      xyz="0 0 0"
      rpy="0 0 0" />
    <parent
      link="base_link" />
    <child
      link="roll_pitch_link" />
    <axis
      xyz="1 0 0" />
    <limit
      lower="-0.69813170079"
      upper="0.69813170079"
      effort="150"
      velocity="500" />
  </joint>
  <link
    name="pitch_slide_link">
    <inertial>
      <origin
        xyz="-0.00583 -0.00105 -0.00041"
        rpy="0 0 0" />
      <mass
        value="0.54748" />
      <inertia
        ixx="0.00066451246"
        ixy="0.00001381471"
        ixz="0.00000679945"
        iyy="0.00069734504"
        iyz="-5.6057e-7"
        izz="0.00051290376" />
    </inertial>
    <visual>
      <origin
        xyz="0 0 0"
        rpy="0 0 0" />
      <geometry>
        <mesh
          filename="../meshes/pitch_slide_link.STL" />
      </geometry>
      <material
        name="">
        <color
          rgba="0.792156862745098 0.819607843137255 0.933333333333333 1" />
      </material>
    </visual>
  </link>
  <joint
    name="pitch"
    type="revolute">
    <origin
      xyz="0 -0.001 0"
      rpy="0 0 0" />
    <parent
      link="roll_pitch_link" />
    <child
      link="pitch_slide_link" />
    <axis
      xyz="0 1 0" />
    <limit
      lower="-0.69813170079"
      upper="0.69813170079"
      effort="150"
      velocity="500" />
  </joint>
  <link
    name="leg_link">
    <inertial>
      <origin
        xyz="0.0 0.00001 0.0"
        rpy="0 0 0" />
      <mass
        value="0.616" />
      <inertia
        ixx="0.08657454998"
        ixy="0.00"
        ixz="0.00"
        iyy="0.0001891915"
        iyz="-3e-11"
        izz="0.08657454948" />
    </inertial>
    <visual>
      <origin
        xyz="0 0 0"
        rpy="0 0 0" />
      <geometry>
        <mesh
          filename="../meshes/leg_link.STL" />
      </geometry>
      <material
        name="">
        <color
          rgba="0.792156862745098 0.819607843137255 0.933333333333333 1" />
      </material>
    </visual>
    <collision>
      <origin
        xyz="0 0 -0.532"
        rpy="0 0 0" /> 
      <geometry>
        <sphere radius="0.033" />
      </geometry>
    </collision>
  </link>
  <joint
    name="slide"
    type="prismatic">
    <origin
      xyz="0 0 0"
      rpy="0 0 0" />
    <parent
      link="pitch_slide_link" />
    <child
      link="leg_link" />
    <axis
      xyz="0 0 1" />
    <limit
      lower="-0.5"
      upper="0.5"
      effort="1500"
      velocity="20" />
  </joint>

</robot>